# Fix pour le Drag & Drop SafeRename

## Problème Identifié

L'utilisateur rapportait que le SafeRename fonctionne correctement pour le renommage manuel, mais ne se déclenche pas pour le drag & drop. Après analyse approfondie, le problème était que :

1. **Le SafeRename était bien appelé** dans le drag & drop
2. **Mais en cas d'erreur technique** (comme une erreur réseau 404), la méthode retournait simplement `False`
3. **Le code de drag & drop** faisait un simple `return` sans informer l'utilisateur
4. **L'utilisateur ne voyait aucune boîte de dialogue** et pensait que SafeRename n'était pas appelé

## Solution Implémentée

### 1. Modification de `_perform_safe_rename_check()`

**Avant :** Retournait simplement `bool`
```python
def _perform_safe_rename_check(self, file_info, meta):
    # ...
    return True  # ou False
```

**Après :** Retourne un dictionnaire avec des informations détaillées
```python
def _perform_safe_rename_check(self, file_info, meta):
    # ...
    return {
        'proceed': bool,        # True si le renommage doit continuer
        'reason': str,          # Raison du résultat
        'user_cancelled': bool  # True si l'utilisateur a explicitement annulé
    }
```

### 2. Cas de retour détaillés

| Situation | `proceed` | `reason` | `user_cancelled` |
|-----------|-----------|----------|------------------|
| Correspondance trouvée | `True` | `"Cover match (score: 0.85)"` | `False` |
| Pas d'URL de couverture | `True` | `"No cover URL available"` | `False` |
| Utilisateur accepte mismatch | `True` | `"User approved mismatch (score: 0.3)"` | `False` |
| Utilisateur refuse mismatch | `False` | `"User rejected mismatch (score: 0.3)"` | `True` |
| Erreur technique | `False` | `"Error: Failed to download image"` | `False` |
| Dépendances manquantes | `True` | `"Dependencies missing"` | `False` |

### 3. Mise à jour du code appelant

**Renommage manuel :** `comicsFileRenamer_v3.py`
```python
# Avant
success = self._perform_safe_rename_check(f, meta)
if not success:
    return

# Après  
result = self._perform_safe_rename_check(f, meta)
if not result['proceed']:
    print(f"[DEBUG] SafeRename - Rename cancelled: {result['reason']}")
    return
```

**Drag & Drop :** `ui/tables.py`
```python
# Avant
proceed = self.main._perform_safe_rename_check(f, meta)
if not proceed:
    return

# Après
result = self.main._perform_safe_rename_check(f, meta)
if not result['proceed']:
    print(f"[DEBUG] Drop - Rename cancelled: {result['reason']}")
    if result['user_cancelled']:
        print(f"[DEBUG] Drop - User explicitly cancelled")
    return
```

## Avantages de la Solution

1. **Transparence :** Les logs montrent maintenant pourquoi SafeRename a échoué
2. **Distinction :** On peut différencier entre annulation utilisateur et erreur technique
3. **Debuggage :** Plus facile d'identifier les problèmes
4. **Cohérence :** Le comportement est maintenant identique entre manuel et drag & drop

## Test de Validation

Le test `test_corrected_drag_drop.py` confirme que :
- ✅ SafeRename est bien appelé pour le drag & drop
- ✅ Les erreurs techniques sont correctement détectées
- ✅ Les messages de debug sont informatifs
- ✅ Le renommage s'arrête proprement en cas d'erreur

## Résultat

Le problème était **une erreur de perception** : SafeRename était appelé mais les erreurs techniques étaient silencieuses. Maintenant, l'utilisateur verra dans les logs que SafeRename a été appelé et pourquoi il a échoué.

**Note :** Pour une expérience utilisateur optimale, les messages de debug peuvent être remplacés par des notifications utilisateur visibles dans une future version.
